<?xml version="1.0" ?>
<robot name="spot" xmlns:xacro="http://www.ros.org/wiki/xacro">
  <link name="body">
    <inertial>
      <origin xyz="0.004809 0.000034 0.002237" rpy="0 0 0" />
      <mass value="16.7025843015913" />
      <inertia ixx="0.1065076385293" ixy="-0.000127647906668351" ixz="0.00752667851730235" iyy="0.9648051370927" iyz="0.0000531096236423339" izz="0.98848474008588" />
    </inertial>
    <visual>
      <origin xyz="0 0 0" rpy="0 0 0" />
      <geometry>
        <mesh filename="file:///Users/namirjawdat/Projects/underactuatedFinalProject/spot_ros/spot_description/meshes/body.dae" />
      </geometry>
    </visual>
    <!-- <collision>
      <origin xyz="0 0 0" rpy="1.570796326794897 0 0" />
      <geometry>
        <mesh filename="file:///Users/namirjawdat/Projects/underactuatedFinalProject/spot_ros/spot_description/meshes/body_collision.obj" />
      </geometry>
    </collision> -->
  </link>

  <!-- <link name="base_link"/>
  <joint name="base_link_joint" type="fixed">
    <origin xyz="0 0 0" rpy="0 0 0" />
    <parent link="body" />
    <child link="base_link" />
  </joint>

    <link name="front_rail"/>
    <joint name="front_rail_joint" type="fixed">
        <origin xyz="0.223 0 0.0805" rpy="0 0 0" />
        <parent link="body" />
        <child link="front_rail" />
    </joint>

    <link name="real_front_rail"/>
    <joint name="real_front_rail_joint" type="fixed">
        <origin xyz="0.2075 0 0.0805" rpy="0 0 0" />
        <parent link="body" />
        <child link="real_front_rail" />
    </joint>

    <link name="rear_rail"/>
    <joint name="rear_rail_joint" type="fixed">
        <origin xyz="-0.223 0 0.0805" rpy="0 0 0" />
        <parent link="body" />
        <child link="rear_rail" />
    </joint>

    <link name="real_rear_rail"/>
    <joint name="real_rear_rail_joint" type="fixed">
        <origin xyz="-0.415 0 0" rpy="0 0 0" />
        <parent link="real_front_rail" />
        <child link="real_rear_rail" />
    </joint> -->

  <link name="front_left_hip">
    <inertial>
      <origin xyz="-0.021594 0.011931 -0.000853" rpy="0 0 0" />
      <mass value="0.756791487749432" />
      <inertia ixx="0.00120774835817126" ixy="-0.000122325587269513" ixz="-0.0000122242990654206" iyy="0.00180646541108866" iyz="0.00000765567378125789" izz="0.00191790889429149" />
    </inertial>
    <visual>
      <origin xyz="0 0 0" rpy="-1.570796326794897 0 0" />
      <geometry>
        <mesh filename="file:///Users/namirjawdat/Projects/underactuatedFinalProject/spot_ros/spot_description/meshes/front_left_hip.dae" />
      </geometry>
    </visual>
    <collision>
      <geometry>
        <mesh filename="file:///Users/namirjawdat/Projects/underactuatedFinalProject/spot_ros/spot_description/meshes/front_left_hip_collision.obj" />
      </geometry>
    </collision>
  </link>

  <joint name="front_left_hip_roll" type="revolute">
    <origin xyz="0.29785 0.05500 0.00000" rpy="1.570796326794897 0 0" />
    <axis xyz="1 0 0" />
    <parent link="body" />
    <child link="front_left_hip" />
    <limit lower="-0.78539816339744827899" upper="0.78539816339744827899" />
    <!-- <limit effort="1000" velocity="1000.00" lower="-0.78539816339744827899" upper="0.78539816339744827899" /> -->
  </joint>

  <transmission type="SimpleTransmission">
    <joint name="front_left_hip_roll"/>
    <actuator name="front_left_hip_roll"/>
  </transmission>

  <link name="front_left_upper_leg">
    <inertial>
      <origin xyz="0.002341 0.003056 -0.111288" rpy="0 0 0" />
      						
      <mass value="2.15112559989896" />
      <inertia ixx="0.0311784567757009" ixy="-0.0000365696514271281" ixz="0.000852211227582723" iyy="0.0305503817883304" iyz="0.00124412700492549" izz="0.00387948042434958" />
    </inertial>
    <visual>
      <origin xyz="0 0 0" rpy="-1.570796326794897 0 0" />
      <geometry>
        <mesh filename="file:///Users/namirjawdat/Projects/underactuatedFinalProject/spot_ros/spot_description/meshes/front_left_upper_leg.dae" />
      </geometry>
    </visual>
    <collision>
      <geometry>
        <mesh filename="file:///Users/namirjawdat/Projects/underactuatedFinalProject/spot_ros/spot_description/meshes/front_left_upper_leg_collision.obj" />
      </geometry>
    </collision>
  </link>

  <joint name="front_left_hip_pitch" type="revolute">
    <origin xyz="0.0 0.0 -0.11" rpy="0 0 0" />
    <axis xyz="0 0 1" />
    <parent link="front_left_hip" />
    <child link="front_left_upper_leg" />
    <limit lower="-2.460914245312005" upper="0.715584993317675" />
    <!-- <limit effort="1000" velocity="1000.00" lower="-0.89884456477707963539" upper="2.2951079663725435509" /> -->
  </joint>

  <transmission type="SimpleTransmission">
    <joint name="front_left_hip_pitch"/>
    <actuator name="front_left_hip_pitch"/>
  </transmission>

  <link name="front_left_lower_leg">
    <inertial>
      <origin xyz="0.006878 0.001493 -0.175910" rpy="0 0 0" />
      					
      <mass value="0.720139239706997" />
      <inertia ixx="0.0110974644165193" ixy="0.0000000929211922202576" ixz="0.0000894882703965648" iyy="0.0112150355361202" iyz="-0.0000326101761808538" izz="0.000439925059989896" />
    </inertial>
    <visual>
      <origin xyz="0 0 0" rpy="-1.570796326794897 0 0" />
      <geometry>
        <mesh filename="file:///Users/namirjawdat/Projects/underactuatedFinalProject/spot_ros/spot_description/meshes/front_left_lower_leg.dae" />
      </geometry>
    </visual>
    <visual>
      <origin xyz="0.0 -0.339 0.00225"/>
      <geometry>
        <sphere radius="0.033"/>
      </geometry>
      <material name="black">
      	<color rgba="0.1 0.1 0.1 0.3" />
      </material>
    </visual>
    <collision>
      <geometry>
        <mesh filename="file:///Users/namirjawdat/Projects/underactuatedFinalProject/spot_ros/spot_description/meshes/front_left_lower_leg_collision.obj" />
      </geometry>
    </collision>
    <collision>
      <origin xyz="0.0 -0.339 0.00225"/>
      <geometry>
        <sphere radius="0.033"/>
      </geometry>
    </collision>
  </link>

  <joint name="front_left_knee" type="revolute">
    <origin xyz="0.025 -0.319 0.0" rpy="0 0 0" />
    <axis xyz="0 0 1" />
    <parent link="front_left_upper_leg" />
    <child link="front_left_lower_leg" />
    <limit lower="0.244346095279206" upper="2.792526803190927" />
    <!-- <limit effort="1000" velocity="1000.00" lower="-2.7929" upper="-0.254801" /> -->
  </joint>

  <transmission type="SimpleTransmission">
    <joint name="front_left_knee"/>
    <actuator name="front_left_knee"/>
  </transmission>

  <frame link="front_left_lower_leg" name="front_left_foot_center" xyz="0.0 -0.339 0.00225"/>

  <link name="front_right_hip">
    <inertial>
      <origin xyz="-0.021565 -0.012054 -0.000772" rpy="0 0 0" />
      <mass value="0.756791487749432" />
      <inertia ixx="0.00121337009030058" ixy="0.000122841816115181" ixz="-0.0000137316872947714" iyy="0.00180859743622127" iyz="-0.00000418145364991159" izz="0.00192084107413488" />
    </inertial>
    <visual>
      <origin xyz="0 0 0" rpy="-1.570796326794897 0 0" />
      <geometry>
        <mesh filename="file:///Users/namirjawdat/Projects/underactuatedFinalProject/spot_ros/spot_description/meshes/front_right_hip.dae" />
      </geometry>
    </visual>
    <collision>
      <geometry>
        <mesh filename="file:///Users/namirjawdat/Projects/underactuatedFinalProject/spot_ros/spot_description/meshes/front_right_hip_collision.obj" />
      </geometry>
    </collision>
  </link>

  <joint name="front_right_hip_roll" type="revolute">
    <origin xyz="0.29785 -0.05500 0.00000" rpy="1.570796326794897 0 0" />
    <axis xyz="1 0 0" />
    <parent link="body" />
    <child link="front_right_hip" />
    <limit lower="-0.78539816339744827899" upper="0.78539816339744827899" />
    <!-- <limit effort="1000" velocity="1000.00" lower="-0.78539816339744827899" upper="0.78539816339744827899" /> -->
  </joint>

  <transmission type="SimpleTransmission">
    <joint name="front_right_hip_roll"/>
    <actuator name="front_right_hip_roll"/>
  </transmission>

  <link name="front_right_upper_leg">
    <inertial>
      <origin xyz="0.002254 -0.003185 -0.111253" rpy="0 0 0" />
      <mass value="2.15112559989896" />
      <inertia ixx="0.0311965454344531" ixy="0.0000380202544834554" ixz="0.000859582975498863" iyy="0.0305693170623895" iyz="-0.00127139421255368" izz="0.0038813130367517" />
    </inertial>
    <visual>
      <origin xyz="0 0 0" rpy="-1.570796326794897 0 0" />
      <geometry>
        <mesh filename="file:///Users/namirjawdat/Projects/underactuatedFinalProject/spot_ros/spot_description/meshes/front_right_upper_leg.dae" />
      </geometry>
    </visual>
    <collision>
      <geometry>
        <mesh filename="file:///Users/namirjawdat/Projects/underactuatedFinalProject/spot_ros/spot_description/meshes/front_right_upper_leg_collision.obj" />
      </geometry>
    </collision>
  </link>
    
  <joint name="front_right_hip_pitch" type="revolute">
    <origin xyz="0.0 0.0 0.11" rpy="0 0 0" />
    <axis xyz="0 0 1" />
    <parent link="front_right_hip" />
    <child link="front_right_upper_leg" />
    <limit lower="-2.460914245312005" upper="0.715584993317675" />
    <!-- <limit effort="1000" velocity="1000.00" lower="-0.89884456477707963539" upper="2.2951079663725435509" /> -->
  </joint>

  <transmission type="SimpleTransmission">
    <joint name="front_right_hip_pitch"/>
    <actuator name="front_right_hip_pitch"/>
  </transmission>

  <link name="front_right_lower_leg">
    <inertial>
      <origin xyz="0.006958 -0.002006 -0.175946" rpy="0 0 0" />
      <mass value="0.720139239706997" />
      <inertia ixx="0.0110986207691336" ixy="0.000000170355519070472" ixz="0.000087640171129073" iyy="0.0112165067883304" iyz="0.0000194050423086638" izz="0.000440276095604951" />
    </inertial>
    <visual>
      <origin xyz="0 0 0" rpy="-1.570796326794897 0 0" />
      <geometry>
        <mesh filename="file:///Users/namirjawdat/Projects/underactuatedFinalProject/spot_ros/spot_description/meshes/front_right_lower_leg.dae" />
      </geometry>
    </visual>
    <visual>
      <origin xyz="0.0 -0.339 0.00225"/>
      <geometry>
        <sphere radius="0.033"/>
      </geometry>
      <material name="black">
      	<color rgba="0.1 0.1 0.1 0.3" />
      </material>
    </visual>
    <collision>
      <geometry>
        <mesh filename="file:///Users/namirjawdat/Projects/underactuatedFinalProject/spot_ros/spot_description/meshes/front_right_lower_leg_collision.obj" />
      </geometry>
    </collision>
    <collision>
      <origin xyz="0.0 -0.339 0.00225"/>
      <geometry>
        <sphere radius="0.033"/>
      </geometry>
    </collision>
  </link>

  <joint name="front_right_knee" type="revolute">
    <origin xyz="0.025 -0.319 0.0" rpy="0 0 0" />
    <axis xyz="0 0 1" />
    <parent link="front_right_upper_leg" />
    <child link="front_right_lower_leg" />
    <limit lower="0.244346095279206" upper="2.792526803190927" />
    <!-- <limit effort="1000" velocity="1000.00" lower="-2.7929" upper="-0.247563" /> -->
  </joint>

  <transmission type="SimpleTransmission">
    <joint name="front_right_knee"/>
    <actuator name="front_right_knee"/>
  </transmission>

  <frame link="front_right_lower_leg" name="front_right_foot_center" xyz="0.0 -0.339 0.00225"/>

  <link name="rear_left_hip">
    <inertial>
      <origin xyz="0.021682 0.012004 -0.000661" rpy="0 0 0" />
      <mass value="0.756791487749432" />
      <inertia ixx="0.00122448449734782" ixy="0.000126729019323061" ixz="0.0000122191367769639" iyy="0.00181365647890882" iyz="0.000000836290729982319" izz="0.00193590463185148" />
    </inertial>
    <visual>
      <origin xyz="0 0 0" rpy="-1.570796326794897 0 0" />
      <geometry>
        <mesh filename="file:///Users/namirjawdat/Projects/underactuatedFinalProject/spot_ros/spot_description/meshes/rear_left_hip.dae" />
      </geometry>
    </visual>
    <collision>
      <geometry>
        <mesh filename="file:///Users/namirjawdat/Projects/underactuatedFinalProject/spot_ros/spot_description/meshes/rear_left_hip_collision.obj" />
      </geometry>
    </collision>
  </link>

  <joint name="rear_left_hip_roll" type="revolute">
    <origin xyz="-0.29785 0.05500 0.00000" rpy="1.570796326794897 0 0" />
    <axis xyz="1 0 0" />
    <parent link="body" />
    <child link="rear_left_hip" />
    <limit lower="-0.78539816339744827899" upper="0.78539816339744827899" />
    <!-- <limit effort="1000" velocity="1000.00" lower="-0.78539816339744827899" upper="0.78539816339744827899" /> -->
  </joint>

  <transmission type="SimpleTransmission">
    <joint name="rear_left_hip_roll"/>
    <actuator name="rear_left_hip_roll"/>
  </transmission>

  <link name="rear_left_upper_leg">
    <inertial>
      <origin xyz="0.002219 0.002914 -0.111421" rpy="0 0 0" />
      <mass value="2.15112559989896" />
      <inertia ixx="0.031158313526143" ixy="-0.0000335239012376863" ixz="0.000868720226067189" iyy="0.0305423441052033" iyz="0.00119244733518565" izz="0.00386811822745643" />
    </inertial>
    <visual>
      <origin xyz="0 0 0" rpy="-1.570796326794897 0 0" />
      <geometry>
        <mesh filename="file:///Users/namirjawdat/Projects/underactuatedFinalProject/spot_ros/spot_description/meshes/rear_left_upper_leg.dae" />
      </geometry>
    </visual>
    <collision>
      <geometry>
        <mesh filename="file:///Users/namirjawdat/Projects/underactuatedFinalProject/spot_ros/spot_description/meshes/rear_left_upper_leg_collision.obj" />
      </geometry>
    </collision>
  </link>

  <joint name="rear_left_hip_pitch" type="revolute">
    <origin xyz="0.0 0.0 -0.11" rpy="0 0 0" />
    <axis xyz="0 0 1" />
    <parent link="rear_left_hip" />
    <child link="rear_left_upper_leg" />
    <limit lower="-2.460914245312005" upper="0.715584993317675" />
    <!-- <limit effort="1000" velocity="1000.00" lower="-0.89884456477707963539" upper="2.2951079663725435509" /> -->
  </joint>

  <transmission type="SimpleTransmission">
    <joint name="rear_left_hip_pitch"/>
    <actuator name="rear_left_hip_pitch"/>
  </transmission>

  <link name="rear_left_lower_leg">
    <inertial>
      <origin xyz="0.006659 0.001625 -0.175832" rpy="0 0 0" />
      						
      <mass value="0.720139239706997" />
      <inertia ixx="0.0110892254041425" ixy="-0.000000851777595352362" ixz="0.0000737587774690578" iyy="0.0112056246842637" iyz="0.00000427437484213185" izz="0.000438257640818388" />
    </inertial>
    <visual>
      <origin xyz="0 0 0" rpy="-1.570796326794897 0 0" />
      <geometry>
        <mesh filename="file:///Users/namirjawdat/Projects/underactuatedFinalProject/spot_ros/spot_description/meshes/rear_left_lower_leg.dae" />
      </geometry>
    </visual>
    <visual>
      <origin xyz="0.0 -0.339 0.00225"/>
      <geometry>
        <sphere radius="0.033"/>
      </geometry>
      <material name="black">
      	<color rgba="0.1 0.1 0.1 0.3" />
      </material>
    </visual>
    <collision>
      <geometry>
        <mesh filename="file:///Users/namirjawdat/Projects/underactuatedFinalProject/spot_ros/spot_description/meshes/rear_left_lower_leg_collision.obj" />
      </geometry>
    </collision>
    <collision>
      <origin xyz="0.0 -0.339 0.00225"/>
      <geometry>
        <sphere radius="0.033"/>
      </geometry>
    </collision>
  </link> 

  <joint name="rear_left_knee" type="revolute">
    <origin xyz="0.025 -0.319 0.0" rpy="0 0 0" />
    <axis xyz="0 0 1" />
    <parent link="rear_left_upper_leg" />
    <child link="rear_left_lower_leg" />
    <limit lower="0.244346095279206" upper="2.792526803190927" />
    <!-- <limit effort="1000" velocity="1000.00" lower="-2.7929" upper="-0.267153" /> -->
  </joint>

  <transmission type="SimpleTransmission">
    <joint name="rear_left_knee"/>
    <actuator name="rear_left_knee"/>
  </transmission>

  <frame link="rear_left_lower_leg" name="rear_left_foot_center" xyz="0.0 -0.339 0.00225"/>

  <link name="rear_right_hip"> 
    <inertial>
      <origin xyz="0.021709 -0.011993 -0.000648" rpy="0 0 0" />
      <mass value="0.756791487749432" />
      <inertia ixx="0.00122605383303865" ixy="-0.000126889050265218" ixz="0.0000125598478151048" iyy="0.00181415205860066" iyz="-0.000000877589037635767" izz="0.0019359252810053" />
    </inertial>
    <visual>
      <origin xyz="0 0 0" rpy="-1.570796326794897 0 0" />
      <geometry>
        <mesh filename="file:///Users/namirjawdat/Projects/underactuatedFinalProject/spot_ros/spot_description/meshes/rear_right_hip.dae" />
      </geometry>
    </visual>
    <collision>
      <geometry>
          <mesh filename="file:///Users/namirjawdat/Projects/underactuatedFinalProject/spot_ros/spot_description/meshes/rear_right_hip_collision.obj" />
      </geometry>
    </collision>
  </link>

  <joint name="rear_right_hip_roll" type="revolute">
    <origin xyz="-0.29785 -0.05500 0.00000" rpy="1.570796326794897 0 0" />
    <axis xyz="1 0 0" />
    <parent link="body" />
    <child link="rear_right_hip" />
    <limit lower="-0.78539816339744827899" upper="0.78539816339744827899" />
    <!-- <limit effort="1000" velocity="1000.00" lower="-0.78539816339744827899" upper="0.78539816339744827899" /> -->
  </joint>

  <transmission type="SimpleTransmission">
    <joint name="rear_right_hip_roll"/>
    <actuator name="rear_right_hip_roll"/>
  </transmission>

  <link name="rear_right_upper_leg">
    <inertial>
      <origin xyz="0.002229 -0.002974 -0.111411" rpy="0 0 0" />
      <mass value="2.15112559989896" />
      <inertia ixx="0.0311915535015155" ixy="0.0000351035615054307" ixz="0.000888037509472089" iyy="0.0305721408341753" iyz="-0.00121686495958575" izz="0.00387716771912099" />
    </inertial>
    <visual>
      <origin xyz="0 0 0" rpy="-1.570796326794897 0 0" />
      <geometry>
        <mesh filename="file:///Users/namirjawdat/Projects/underactuatedFinalProject/spot_ros/spot_description/meshes/rear_right_upper_leg.dae" />
      </geometry>
    </visual>
    <collision>
      <geometry>
        <mesh filename="file:///Users/namirjawdat/Projects/underactuatedFinalProject/spot_ros/spot_description/meshes/rear_right_upper_leg_collision.obj" />
      </geometry>
    </collision>
  </link>

  <joint name="rear_right_hip_pitch" type="revolute">
    <origin xyz="0.0 0.0 0.11" rpy="0 0 0" />
    <axis xyz="0 0 1" />
    <parent link="rear_right_hip" />
    <child link="rear_right_upper_leg" />
    <limit lower="-2.460914245312005" upper="0.715584993317675" />
    <!-- <limit effort="1000" velocity="1000.00" lower="-0.89884456477707963539" upper="2.2951079663725435509" /> -->
  </joint>

  <transmission type="SimpleTransmission">
    <joint name="rear_right_hip_pitch"/>
    <actuator name="rear_right_hip_pitch"/>
  </transmission>

  <link name="rear_right_lower_leg">
    <inertial>
      <origin xyz="0.006799 -0.001949 -0.175935" rpy="0 0 0" />
      <mass value="0.720139239706997" />
      <inertia ixx="0.0111049652216469" ixy="0.000000438794518817883" ixz="0.0000764999526395554" iyy="0.0112211734970952" iyz="-0.00001322062073756" izz="0.000439155879009851" />
    </inertial>
    <visual>
      <origin xyz="0 0 0" rpy="-1.570796326794897 0 0" />
      <geometry>
        <mesh filename="file:///Users/namirjawdat/Projects/underactuatedFinalProject/spot_ros/spot_description/meshes/rear_right_lower_leg.dae" />
      </geometry>
    </visual>
    <visual>
      <origin xyz="0.0 -0.339 0.00225"/>
      <geometry>
        <sphere radius="0.033"/>
      </geometry>
      <material name="black">
      	<color rgba="0.1 0.1 0.1 0.3" />
      </material>
    </visual>
    <collision>
      <origin xyz="0 0 0" rpy="0 0 0" />
      <geometry>
        <mesh filename="file:///Users/namirjawdat/Projects/underactuatedFinalProject/spot_ros/spot_description/meshes/rear_right_lower_leg_collision.obj" />
      </geometry>
    </collision>
    <collision>
      <origin xyz="0.0 -0.339 0.00225"/>
      <geometry>
        <sphere radius="0.033"/>
      </geometry>
    </collision>
  </link>


  <joint name="rear_right_knee" type="revolute">
    <origin xyz="0.025 -0.319 0.0" rpy="0 0 0" />
    <axis xyz="0 0 1" />
    <parent link="rear_right_upper_leg" />
    <child link="rear_right_lower_leg" />
    <limit lower="0.244346095279206" upper="2.792526803190927" />
    <!-- <limit effort="1000" velocity="1000.00" lower="-2.7929" upper="-0.257725" /> -->
  </joint>

  <transmission type="SimpleTransmission">
    <joint name="rear_right_knee"/>
    <actuator name="rear_right_knee"/>
  </transmission>
  
  <frame link="rear_right_lower_leg" name="rear_right_foot_center" xyz="0.0 -0.339 0.00225"/>
    
  <!-- Adding The Arm -->
  <link name="arm_base">
    <inertial>
      <origin xyz="0.0	0.0	0.0325005" rpy="0 0 0"/>
      <mass value="8.4470803421374E-01"/>
      <inertia ixx="1.05642448858263E-03" ixy="0.0" ixz="0.0" iyy="1.05642448858263E-03" iyz="0.0" izz="1.51803384389596E-03"/>
    </inertial>
    <visual>
      <origin rpy="0 0 0" xyz="0 0 0"/>
      <geometry>
        <mesh filename="file:///Users/namirjawdat/Projects/underactuatedFinalProject/spot_ros/spot_description/meshes/arm/arm_base.obj" scale="0.001 0.001 0.001"/>
      </geometry>
    </visual>
    <collision>
      <origin rpy="0 0 0" xyz="0 0 0"/>
      <geometry>
        <mesh filename="file:///Users/namirjawdat/Projects/underactuatedFinalProject/spot_ros/spot_description/meshes/arm/arm_base.obj" scale="0.001 0.001 0.001"/>
      </geometry>
     </collision>
  </link>

  <joint name="arm_base" type="fixed">
    <origin xyz="0.29 0.0 0.11" rpy="1.570796326794897 0 0" />
    <parent link="body" />
    <child link="arm_base" />
  </joint>

 <link name="shoulder">
    <inertial>
      <origin xyz="0.050693264 0.000000002 0.111764267" rpy="0 0 0"/>
      <mass value="1.01412247519236E+00"/>
      <inertia ixx="1.8154556264852E-03" ixy="6.32940438316485E-11" ixz="-1.53051526788674E-04" iyy="1.5196014291069E-03" iyz="8.54782331794787E-11" izz="1.79976798912846E-03"/>
    </inertial>
    <visual>
      <origin xyz="0.0599 0.074 0.0" rpy="0 0 0"/>
      <geometry>
        <mesh filename="file:///Users/namirjawdat/Projects/underactuatedFinalProject/spot_ros/spot_description/meshes/arm/shoulder.obj" scale="0.001 0.001 0.001"/>
      </geometry>
    </visual>
    <collision>
      <origin xyz="0.0599 0.074 0.0" rpy="0 0 0"/>
      <geometry>
        <mesh filename="file:///Users/namirjawdat/Projects/underactuatedFinalProject/spot_ros/spot_description/meshes/arm/shoulder.obj" scale="0.001 0.001 0.001"/>
      </geometry>
    </collision>
  </link>

  <joint name="shoulder_roll" type="revolute">
    <origin xyz="0.0 0.0 0.0" rpy="0 1.570796326794897 0"/>
    <parent link="arm_base"/>
    <child link="shoulder"/>
    <axis xyz="0.0 -1.0 0.0"/>
    <limit lower="0.0" upper="5.759586531581288"/>
    <!-- <limit effort="100" lower="-3.141593" upper="2.617994" velocity="100"/> -->
  </joint>

  <transmission type="SimpleTransmission" name="shoulder_roll_force">
    <joint name="shoulder_roll"/>
    <actuator name="shoulder_roll"/>
  </transmission>

  <link name="upper_arm">
    <inertial>
      <origin xyz="-0.001309559 0.175409149	0.115000" rpy="0 0 0"/>
      <mass value="1.85585420216174E+00"/>
      <inertia ixx="1.90287856174162E-02" ixy="3.84903415743162E-04" ixz="-5.46907983164896E-12" iyy="1.47198770403943E-03" iyz="4.09998257343947E-10" izz="1.8985160167362E-02"/>
    </inertial>
    <visual>
      <origin xyz="0 0 -0.14" rpy="0 0 0"/>
      <geometry>
        <mesh filename="file:///Users/namirjawdat/Projects/underactuatedFinalProject/spot_ros/spot_description/meshes/arm/upper_arm.obj" scale="0.001 0.001 0.001"/>
      </geometry>
    </visual>
    <collision>
      <origin xyz="0 0 -0.14" rpy="0 0 0"/>
      <geometry>
        <mesh filename="file:///Users/namirjawdat/Projects/underactuatedFinalProject/spot_ros/spot_description/meshes/arm/upper_arm.obj" scale="0.001 0.001 0.001"/>
      </geometry>
    </collision>
  </link>

  <joint name="shoulder_pitch" type="revolute">
    <origin xyz="0.0 0.09 0.0" rpy="0 0 0"/>
    <!-- <origin xyz="0.0 0.13 -0.02" rpy="0 0 0"/> -->
    <parent link="shoulder"/>
    <child link="upper_arm"/>
    <axis xyz="1.0 0.0 0.0"/>
    <limit lower="0.0" upper="3.665191429188092"/>
    <!-- <limit effort="100" lower="-3.665191429188092" upper="0.0" velocity="100"/> -->
  </joint>

  <transmission type="SimpleTransmission">
    <joint name="shoulder_pitch"/>
    <actuator name="shoulder_pitch"/>
  </transmission>

  <link name="elbow">
    <inertial>
      <origin xyz="0.001378161	0.379156586	0.056925724" rpy="0 0 0"/>
      <mass value="1.08030731359557E+00"/>
      <inertia ixx="2.6497702614337E-03" ixy="1.34200112163595E-04" ixz="-1.48060133875651E-04" iyy="1.72847446122508E-03" iyz="5.46631591493253E-04" izz="2.44406598769231E-03"/>
    </inertial>
    <visual>
      <origin xyz="0.0 -0.07 -0.09" rpy="0 0 0"/>
      <geometry>
        <mesh filename="file:///Users/namirjawdat/Projects/underactuatedFinalProject/spot_ros/spot_description/meshes/arm/elbow.obj" scale="0.001 0.001 0.001"/>
      </geometry>
    </visual>
    <collision>
      <origin xyz="0.0 -0.07 -0.09" rpy="0 0 0"/>
      <geometry>
        <mesh filename="file:///Users/namirjawdat/Projects/underactuatedFinalProject/spot_ros/spot_description/meshes/arm/elbow.obj" scale="0.001 0.001 0.001"/>
      </geometry>
    </collision>
  </link>

  <joint name="elbow_pitch" type="revolute">
    <origin xyz="0.0 0.0 -0.32" rpy="3.141592653589793 0 0"/>
    <parent link="upper_arm"/>
    <child link="elbow"/>
    <axis xyz="-1.0 0.0 0.0"/>
    <limit lower="0.0" upper="3.141592653589793"/>
    <!-- <limit effort="100" lower="0.0" upper="2.96706" velocity="100"/> -->
  </joint>

  <transmission type="SimpleTransmission">
    <joint name="elbow_pitch"/>
    <actuator name="elbow_pitch"/>
  </transmission>

  <link name="lower_arm">
    <inertial>
      <origin xyz="-0.010117033	0.576546326	0.047500" rpy="0 0 0"/>
      <mass value="1.60548660664662E+00"/>
      <inertia ixx="9.78987060807806E-03" ixy="1.75547490481279E-03" ixz="-3.22983323437141E-11" iyy="2.19771041837686E-03" iyz="1.32854267071776E-09" izz="1.054641984655E-02"/>
    </inertial>
    <visual>
      <origin xyz="-0.014473 -0.0 -0.198" rpy="0 0 0"/>
      <geometry>
        <mesh filename="file:///Users/namirjawdat/Projects/underactuatedFinalProject/spot_ros/spot_description/meshes/arm/lower_arm.obj" scale="0.001 0.001 0.001"/>
      </geometry>
    </visual>
    <collision>
      <origin xyz="-0.014473 -0.0 -0.198" rpy="0 0 0"/>
      <geometry>
        <mesh filename="file:///Users/namirjawdat/Projects/underactuatedFinalProject/spot_ros/spot_description/meshes/arm/lower_arm.obj" scale="0.001 0.001 0.001"/>
      </geometry>
    </collision>
  </link>

  <joint name="lower_arm_roll" type="revolute">
    <origin xyz="0.0015 -0.0825 -0.125" rpy="0 0 1.570796326794897"/>
    <parent link="elbow"/>
    <child link="lower_arm"/>
    <axis xyz="0.0 0.0 1.0"/>
    <limit lower="-2.792526803190927" upper="2.792526803190927"/>
    <!-- <limit effort="100" lower="-2.879793" upper="2.879793" velocity="100"/> -->
  </joint>

  <transmission type="SimpleTransmission">
    <joint name="lower_arm_roll"/>
    <actuator name="lower_arm_roll"/>
  </transmission>

  <link name="wrist">
    <inertial>
      <origin xyz="-0.008954922	0.733331	0.047502666" rpy="0 0 0"/>
      <mass value="4.72269042472257E-01"/>
      <inertia ixx="4.95333466649268E-04" ixy="-3.16192719166953E-06" ixz="6.12242158042143E-09" iyy="3.27482191989288E-04" iyz="-7.57843702187199E-09" izz="5.02611482968939E-04"/>
    </inertial>
    <visual>
      <origin xyz="0.036052 0.0 0.015" rpy="0 0 0"/>
      <geometry>
        <mesh filename="file:///Users/namirjawdat/Projects/underactuatedFinalProject/spot_ros/spot_description/meshes/arm/wrist.obj" scale="0.001 0.001 0.001"/>
      </geometry>
    </visual>
    <collision>
      <origin xyz="0.036052 0.0 0.015" rpy="0 0 0"/>
      <geometry>
        <mesh filename="file:///Users/namirjawdat/Projects/underactuatedFinalProject/spot_ros/spot_description/meshes/arm/wrist.obj" scale="0.001 0.001 0.001"/>
      </geometry>
    </collision>
  </link>

  <joint name="wrist_pitch" type="revolute">
    <origin xyz="-0.0474 0.0 -0.26" rpy="0 0 0"/>
    <parent link="lower_arm"/>
    <child link="wrist"/>
    <axis xyz="1.0 0.0 0.0"/>
    <limit lower="-1.570796" upper="1.570796"/>
    <!-- <limit effort="100" lower="-1.570796" upper="1.570796" velocity="100"/> -->
  </joint>

  <transmission type="SimpleTransmission">
    <joint name="wrist_pitch"/>
    <actuator name="wrist_pitch"/>
  </transmission>

  <link name="gripper">
    <inertial>
      <origin xyz="-0.008500081	0.850122681	0.064628716" rpy="0 0 0"/>
      <mass value="8.76161639389477E-01"/>
      <inertia ixx="2.52491911897022E-03" ixy="4.13484121739019E-10" ixz="2.38079372470107E-10" iyy="1.07566861895342E-03" iyz="-5.67240232531871E-04" izz="2.24194546034942E-03"/>
    </inertial>
    <visual>
      <origin xyz="0.00104 0.001921 -0.022094" rpy="0 0 -1.570796326794897"/>
      <geometry>
        <mesh filename="file:///Users/namirjawdat/Projects/underactuatedFinalProject/spot_ros/spot_description/meshes/arm/gripper.obj" scale="0.001 0.001 0.001"/>
      </geometry>
    </visual>
    <collision>
      <origin xyz="0.00104 0.001921 -0.022094" rpy="0 0 -1.570796326794897"/>
      <geometry>
        <mesh filename="file:///Users/namirjawdat/Projects/underactuatedFinalProject/spot_ros/spot_description/meshes/arm/gripper.obj" scale="0.001 0.001 0.001"/>
      </geometry>
    </collision>
  </link>

  <joint name="wrist_roll" type="revolute">
    <origin xyz="0.04 0.0 -0.064" rpy="0 0 0"/>
    <parent link="wrist"/>
    <child link="gripper"/>
    <axis xyz="0.0 0.0 1.0"/>
    <limit lower="-2.879793265790644" upper="2.879793265790644"/>
    <!-- <limit effort="100" lower="-2.96706" upper="2.96706" velocity="100"/> -->
  </joint>

  <transmission type="SimpleTransmission">
    <joint name="wrist_roll"/>
    <actuator name="wrist_roll"/>
  </transmission>

  <link name="finger">
    <inertial>
      <origin xyz="-0.013500088	0.922123901	0.027004997" rpy="0 0 0"/>
      <mass value="2.51090686328227E-01"/>
      <inertia ixx="3.12126309344984E-04" ixy="3.16526931057423E-10" ixz="7.02242238704263E-11" iyy="2.46474508241264E-04" iyz="2.36998538690293E-05" izz="4.99008659201307E-04"/>
    </inertial>
    <visual>
      <origin xyz="0 0.0 -0.073" rpy="0 0 -1.570796326794897"/>
      <geometry>
        <mesh filename="file:///Users/namirjawdat/Projects/underactuatedFinalProject/spot_ros/spot_description/meshes/arm/finger.obj" scale="0.001 0.001 0.001"/>
      </geometry>
    </visual>
    <collision>
      <origin xyz="0 0.0 -0.073" rpy="0 0 -1.570796326794897"/>
      <geometry>
        <mesh filename="file:///Users/namirjawdat/Projects/underactuatedFinalProject/spot_ros/spot_description/meshes/arm/finger.obj" scale="0.001 0.001 0.001"/>
      </geometry>
    </collision>
  </link>

  <joint name="finger_pitch" type="revolute">
    <origin xyz="0 0 -0.04" rpy="0 -0.174532925199433 0"/>
    <parent link="gripper"/>
    <child link="finger"/>
    <axis xyz="0.0 1.0 0.0"/>
    <limit lower="0" upper="1.570796326794897"/>
    <!-- <limit effort="100" lower="-1.396263" upper="0.349066" velocity="100"/> -->
  </joint>

  <transmission type="SimpleTransmission">
    <joint name="finger_pitch"/>
    <actuator name="finger_pitch"/>
  </transmission>
</robot>
